require("regenerator-runtime/runtime")
const test = require('ava').default
const FP = require('../')
const {FunctionalError} = require('../src/modules/errors.js')
/// <reference types="../index.d.ts" />
// const FP = require('../index.d.ts')
const chalk = require('chalk').default

const onUnhandledRejection = (error) => {
  // Will print "unhandledRejection err is not defined"
  console.error('unhandledRejection', error.message)
}

test.before(() => {
  process.on('unhandledRejection', onUnhandledRejection)
})
// test.after(() => {
//   process.off('unhandledRejection', onUnhandledRejection)
// })
test('FunctionalError has expected message', t => {
  const error = new FunctionalError('Oh noes!')
  t.plan(1)
  t.is(error.message, 'Oh noes!')
})

test('FunctionalError has custom properties', t => {
  const error = new FunctionalError('Oh noes!', {custom: 42})
  t.plan(2)
  t.is(error.message, 'Oh noes!')
  t.is(error.custom, 42)
})

test('FunctionalError supports object-based message argument', t => {
  const error = new FunctionalError({message: 'Oh noes!'})
  t.plan(1)
  t.is(error.message, 'Oh noes!')
})

test('FunctionalError supports object-based argument w/ custom properties', t => {
  const error = new FunctionalError({message: 'Oh noes!', custom: 42})
  t.plan(2)
  t.is(error.message, 'Oh noes!')
  t.is(error.custom, 42)
})

test('FP.map handles invalid input arguments', t => {
  t.plan(1)
  return FP.resolve({ tears: true })
    .map(() => t.fail('Should not be called'))
    .then(() => t.fail(`Shouldn't get here!`))
    .catch(ex => {
      t.truthy(ex.message.includes('Value must be iterable'))
    })
})

test('FP.map handles first exception correctly', t => {
  t.plan(1)
  const throwThings = async () => {
    throw new Error('ðŸ”ªðŸ”ªðŸ”ªðŸ”ªðŸ”ªðŸ”ªðŸ”ª')
  }
  return FP.resolve({ tears: true })
    .map(throwThings)
    .then(() => {
      console.error('Should not get here')
      t.fail(`Shouldn't get here!`)
    }).catch(ex => {
      t.truthy(ex.message.includes('ðŸ”ª'), `Failed to get expected message. Instead got: ${ex.message}`)
    })
})

test('Can FP.quiet() Error', t => {
  t.plan(1)
  return FP.resolve([1, 2, 3, 4])
    .quiet(42)
    .map((n) => {
      if (n === 4) {
        return Promise.reject(new TypeError('#4 found, dummy error!'))
      }
      return n
    })
    .then((results) => {
      t.truthy(results[3] instanceof TypeError)
    })
    .catch(err => {
      console.warn(chalk.yellowBright`ERR:`, err.message)
      t.fail('shouldnt get here')
    })
})

test('Can FP.quiet(1) + 2 errors trigger .catch()', t => {
  return FP.resolve([1, 2, 3, 4])
    .quiet(1)
    .map((n) => {
      if (n <= 3) {
        throw new TypeError(n + ' Found #3 or #4 found, dummy error!')
      }
      return n
    })
    .then((results) => t.fail('shouldn\'t get here'))
    .catch(() => t.pass('overflowed .quiet() w/ errors.'))
})

test('Can FP.quiet() swallow Errors', t => {
  return FP.resolve([1, 2, 3, 4])
    .quiet(1)
    .map((n) => {
      if (n === 4) { throw new TypeError('#4 found, dummy error!') }
      return n
    })
    .then((results) => {
      t.truthy(results[3] instanceof TypeError)
    })
    .catch(err => {
      console.log(chalk.cyanBright`FAILED TO QUIET ERROR:`, err)
      t.fail('shouldnt get here')
    })
})

test('Can .catch() thrown Errors', t => {
  return FP.resolve()
    .then(() => {throw new TypeError('Single toss')})
    .tap(() => t.fail('must skip to the .catch section!'))
    .catch(err => t.truthy(err.message === 'Single toss'))
})

test('Can override .catch() results', t => {
  return FP.resolve()
    .then(() => {throw new TypeError('Single toss')})
    .tap(() => t.fail('must skip to the .catch section!'))
    .catch(err => ({message: 'temp error, plz try again', _err: err}))
    .then(data => t.truthy(data.message === 'temp error, plz try again'))
})

test('Does .catchIf(filterType, fn) filtering by TypeError', t => {
  return FP.resolve()
    .then(() => {throw new Error('Oh noes')})
    .tap(() => t.fail('must skip to the .catch section!'))
    .catchIf(TypeError, () => t.fail('arg too specific for .catch(type)'))
    .catchIf(SyntaxError, () => t.fail('arg too specific for .catch(type)'))
    .catchIf(ReferenceError, () => t.fail('arg too specific for .catch(type)'))
    .catch(err => t.truthy(err.message === 'Oh noes'))
})

test('Does .catchIf(filterType, fn) skip negative tests', t => {
  return FP.resolve()
    .then(() => {throw new TypeError('Oh noes')})
    .tap(() => t.fail('must skip to the .catch section!'))
    .catchIf(ReferenceError, () => t.fail('arg too specific for .catch(type)'))
    .catchIf(SyntaxError, () => t.fail('arg too specific for .catch(type)'))
    .catchIf(TypeError, () => t.pass('successfully filtered .catch(type)'))
    .catch(err => t.fail(err.message === 'Oh noes'))
})


test('Does .catch(filterType, fn) filtering by TypeError', t => {
  return FP.resolve()
    .then(() => {throw new Error('Oh noes')})
    .tap(() => t.fail('must skip to the .catch section!'))
    .catch(TypeError, () => t.fail('arg too specific for .catch(type)'))
    .catch(SyntaxError, () => t.fail('arg too specific for .catch(type)'))
    .catch(ReferenceError, () => t.fail('arg too specific for .catch(type)'))
    .catch(err => t.truthy(err.message === 'Oh noes'))
})

test('Does .catch(filterType, fn) skip negative tests', t => {
  return FP.resolve()
    .then(() => {throw new TypeError('Oh noes')})
    .tap(() => t.fail('must skip to the .catch section!'))
    .catch(ReferenceError, () => t.fail('arg too specific for .catch(type)'))
    .catch(SyntaxError, () => t.fail('arg too specific for .catch(type)'))
    .catch(TypeError, () => t.pass('successfully filtered .catch(type)'))
    .catch(err => t.fail(err.message === 'Oh noes'))
})

test('Can override .catch() w/ .chain()', t => {
  const pipeline = FP.chain()
    .map(() => FP.reject(new Error('Fail!')))
    .chainEnd()

  return pipeline([1])
    .then(result => {
      // console.log(result)
      t.fail('FAIL: unexpected .then hit')
    })
    .catch(() => t.pass('Testing Expected Error'))
})

test('Can override .catch() w/ .chain().quiet()', t => {
  const pipeline = FP.chain()
    .quiet(3)
    .map(() => FP.reject(new Error('Fail!')))
    .chainEnd()

  return Promise.all([
    pipeline([1])
      .then(() => t.pass('Silenced err correctly!'))
      .catch(() => t.fail('Error failed .quiet()')),
    pipeline([1, 2, 3 ,4])
      .then(() => t.fail('FAIL: Should have fired a .catch()!'))
      .catch(() => t.pass('Success: Exceeded .quiet() error limit'))
  ])
})
